<?xml version="1.0" encoding="utf-8"?>
<!-- This URDF was automatically created by SolidWorks to URDF Exporter! Originally created by Stephen Brawner (brawner@gmail.com) 
     Commit Version: 1.5.1-0-g916b5db  Build Version: 1.5.7152.31018
     For more information, please see http://wiki.ros.org/sw_urdf_exporter -->
<robot
  name="jetsonbot_description">
  <link
    name="base_link">
    <inertial>
      <origin
        xyz="0.0047715 -0.0014807 0.044523"
        rpy="0 0 0" />
      <mass
        value="0.77437" />
      <inertia
        ixx="0.0032455"
        ixy="2.9082E-05"
        ixz="0.00025763"
        iyy="0.0031915"
        iyz="-3.1213E-05"
        izz="0.0037916" />
    </inertial>
    <visual>
      <origin
        xyz="0 0 0"
        rpy="0 0 0" />
      <geometry>
        <mesh
          filename="package://jetsonbot_description/meshes/base_link.STL" />
      </geometry>
      <material
        name="">
        <color
          rgba="0.79216 0.81961 0.93333 1" />
      </material>
    </visual>
    <collision>
      <origin
        xyz="0 0 0"
        rpy="0 0 0" />
      <geometry>
        <mesh
          filename="package://jetsonbot_description/meshes/base_link.STL" />
      </geometry>
    </collision>
  </link>
  <link
    name="left_wheel_link">
    <inertial>
      <origin
        xyz="-2.69089611704132E-08 -0.00435578551819871 -1.31337207914806E-08"
        rpy="0 0 0" />
      <mass
        value="0.0482752493266289" />
      <inertia
        ixx="1.99861431168568E-05"
        ixy="-7.46671916195545E-12"
        ixz="-5.04358554916956E-11"
        iyy="3.45141126358409E-05"
        iyz="-3.14453157602247E-12"
        izz="1.99863129466129E-05" />
    </inertial>
    <visual>
      <origin
        xyz="0 0 0"
        rpy="0 0 0" />
      <geometry>
        <mesh
          filename="package://jetsonbot_description/meshes/left_wheel_link.STL" />
      </geometry>
      <material
        name="">
        <color
          rgba="1 1 1 1" />
      </material>
    </visual>
    <collision>
      <origin
        xyz="0 0 0"
        rpy="0 0 0" />
      <geometry>
        <mesh
          filename="package://jetsonbot_description/meshes/left_wheel_link.STL" />
      </geometry>
    </collision>
  </link>
  <joint
    name="left_wheel_joint"
    type="continuous">
    <origin
      xyz="-0.043881 0.11073 0.0215"
      rpy="0 0 0" />
    <parent
      link="base_link" />
    <child
      link="left_wheel_link" />
    <axis
      xyz="0 1 0" />
  </joint>
  <link
    name="right_wheel_link">
    <inertial>
      <origin
        xyz="1.1532E-09 0.0043558 -2.9921E-08"
        rpy="0 0 0" />
      <mass
        value="0.048275" />
      <inertia
        ixx="1.9986E-05"
        ixy="-7.604E-13"
        ixz="4.2889E-11"
        iyy="3.4514E-05"
        iyz="8.0661E-12"
        izz="1.9986E-05" />
    </inertial>
    <visual>
      <origin
        xyz="0 0 0"
        rpy="0 0 0" />
      <geometry>
        <mesh
          filename="package://jetsonbot_description/meshes/right_wheel_link.STL" />
      </geometry>
      <material
        name="">
        <color
          rgba="1 1 1 1" />
      </material>
    </visual>
    <collision>
      <origin
        xyz="0 0 0"
        rpy="0 0 0" />
      <geometry>
        <mesh
          filename="package://jetsonbot_description/meshes/right_wheel_link.STL" />
      </geometry>
    </collision>
  </link>
  <joint
    name="right_wheel_joint"
    type="continuous">
    <origin
      xyz="-0.043881 -0.11073 0.0215"
      rpy="0 0 0" />
    <parent
      link="base_link" />
    <child
      link="right_wheel_link" />
    <axis
      xyz="0 1 0" />
  </joint>
  <link
    name="laser_link">
    <inertial>
      <origin
        xyz="0.0062631910022847 3.81318568261357E-06 -0.00737888701294895"
        rpy="0 0 0" />
      <mass
        value="0.137819035246882" />
      <inertia
        ixx="5.9983710717641E-05"
        ixy="-1.30731671116671E-08"
        ixz="1.56224391843613E-05"
        iyy="9.38764462656713E-05"
        iyz="1.14801841187963E-08"
        izz="0.000110755733268658" />
    </inertial>
    <visual>
      <origin
        xyz="0 0 0"
        rpy="0 0 0" />
      <geometry>
        <mesh
          filename="package://jetsonbot_description/meshes/laser_link.STL" />
      </geometry>
      <material
        name="">
        <color
          rgba="0.298039215686275 0.298039215686275 0.298039215686275 1" />
      </material>
    </visual>
    <collision>
      <origin
        xyz="0 0 0"
        rpy="0 0 0" />
      <geometry>
        <mesh
          filename="package://jetsonbot_description/meshes/laser_link.STL" />
      </geometry>
    </collision>
  </link>
  <joint
    name="laser_joint"
    type="fixed">
    <origin
      xyz="-0.043232 -0.00027141 0.1765"
      rpy="0 0 0" />
    <parent
      link="base_link" />
    <child
      link="laser_link" />
    <axis
      xyz="0 0 0" />
  </joint>
  <link
    name="niujiaolun_link">
    <inertial>
      <origin
        xyz="0 3.69473578724923E-20 0.0111804892378822"
        rpy="0 0 0" />
      <mass
        value="0.00911013999938701" />
      <inertia
        ixx="6.40056194526272E-07"
        ixy="-4.54373925393991E-23"
        ixz="7.21556510002207E-24"
        iyy="6.11854090718744E-07"
        iyz="7.7905978217612E-25"
        izz="8.12795721176257E-07" />
    </inertial>
    <visual>
      <origin
        xyz="0 0 0"
        rpy="0 0 0" />
      <geometry>
        <mesh
          filename="package://jetsonbot_description/meshes/niujiaolun_link.STL" />
      </geometry>
      <material
        name="">
        <color
          rgba="0.752941176470588 0.752941176470588 0.752941176470588 1" />
      </material>
    </visual>
    <collision>
      <origin
        xyz="0 0 0"
        rpy="0 0 0" />
      <geometry>
        <mesh
          filename="package://jetsonbot_description/meshes/niujiaolun_link.STL" />
      </geometry>
    </collision>
  </link>
  <joint
    name="niujiaolun_joint"
    type="fixed">
    <origin
      xyz="0.092152 0 -0.0059"
      rpy="0 0 0" />
    <parent
      link="base_link" />
    <child
      link="niujiaolun_link" />
    <axis
      xyz="0 0 0" />
  </joint>
</robot>